[2020-10-27 22:52:26,187][Thread-1:6572][task_id:django][views.py:35][ERROR][1]
[2020-10-28 11:28:14,216][Thread-4:12984][task_id:django.request][log.py:230][ERROR][Internal Server Error: /recommendation/]
Traceback (most recent call last):
  File "D:\Projects\Collegiate_Explorer_APP\collegiate-explorer-admin\venv\lib\site-packages\django\core\handlers\exception.py", line 47, in inner
    response = get_response(request)
  File "D:\Projects\Collegiate_Explorer_APP\collegiate-explorer-admin\venv\lib\site-packages\django\core\handlers\base.py", line 179, in _get_response
    response = wrapped_callback(request, *callback_args, **callback_kwargs)
  File "D:\Projects\Collegiate_Explorer_APP\collegiate-explorer-admin\cc_admin\apps\recommendation\views.py", line 78, in index
    logger.info("func 'index' get a param id -> " + id)
TypeError: must be str, not builtin_function_or_method
[2020-10-28 11:28:14,222][Thread-4:12984][task_id:django.server][basehttp.py:157][ERROR]["GET /recommendation/ HTTP/1.1" 500 73639]
[2020-10-28 12:29:56,906][Thread-1:12172][task_id:django.request][log.py:230][ERROR][Internal Server Error: /search]
Traceback (most recent call last):
  File "D:\Projects\Collegiate_Explorer_APP\collegiate-explorer-admin\venv\lib\site-packages\django\core\handlers\exception.py", line 47, in inner
    response = get_response(request)
  File "D:\Projects\Collegiate_Explorer_APP\collegiate-explorer-admin\venv\lib\site-packages\django\utils\deprecation.py", line 113, in __call__
    response = self.process_request(request)
  File "D:\Projects\Collegiate_Explorer_APP\collegiate-explorer-admin\venv\lib\site-packages\django\middleware\common.py", line 54, in process_request
    path = self.get_full_path_with_slash(request)
  File "D:\Projects\Collegiate_Explorer_APP\collegiate-explorer-admin\venv\lib\site-packages\django\middleware\common.py", line 94, in get_full_path_with_slash
    'url': request.get_host() + new_path,
RuntimeError: You called this URL via POST, but the URL doesn't end in a slash and you have APPEND_SLASH set. Django can't redirect to the slash URL while maintaining POST data. Change your form to point to localhost:8000/search/ (note the trailing slash), or set APPEND_SLASH=False in your Django settings.
[2020-10-28 12:29:56,912][Thread-1:12172][task_id:django.server][basehttp.py:157][ERROR]["POST /search HTTP/1.1" 500 78790]
[2020-10-28 16:51:00,218][Thread-3:11272][task_id:django.request][log.py:230][ERROR][Internal Server Error: /search/query]
Traceback (most recent call last):
  File "D:\Projects\Collegiate_Explorer_APP\collegiate-explorer-admin\venv\lib\site-packages\django\core\handlers\exception.py", line 47, in inner
    response = get_response(request)
  File "D:\Projects\Collegiate_Explorer_APP\collegiate-explorer-admin\venv\lib\site-packages\django\core\handlers\base.py", line 179, in _get_response
    response = wrapped_callback(request, *callback_args, **callback_kwargs)
  File "D:\Projects\Collegiate_Explorer_APP\collegiate-explorer-admin\venv\lib\site-packages\django\views\decorators\csrf.py", line 54, in wrapped_view
    return view_func(*args, **kwargs)
  File "D:\Projects\Collegiate_Explorer_APP\collegiate-explorer-admin\cc_admin\apps\search\views.py", line 82, in index
    selected_tags = json.load(filter_content)
  File "C:\Users\AARON-PREDATOR\AppData\Local\Programs\Python\Python36\lib\json\__init__.py", line 296, in load
    return loads(fp.read(),
AttributeError: 'str' object has no attribute 'read'
[2020-10-28 16:51:00,226][Thread-3:11272][task_id:django.server][basehttp.py:157][ERROR]["POST /search/query HTTP/1.1" 500 84971]
[2020-10-28 16:57:38,542][Thread-1:10500][task_id:django.request][log.py:230][ERROR][Internal Server Error: /search/query]
Traceback (most recent call last):
  File "D:\Projects\Collegiate_Explorer_APP\collegiate-explorer-admin\venv\lib\site-packages\django\core\handlers\exception.py", line 47, in inner
    response = get_response(request)
  File "D:\Projects\Collegiate_Explorer_APP\collegiate-explorer-admin\venv\lib\site-packages\django\core\handlers\base.py", line 179, in _get_response
    response = wrapped_callback(request, *callback_args, **callback_kwargs)
  File "D:\Projects\Collegiate_Explorer_APP\collegiate-explorer-admin\venv\lib\site-packages\django\views\decorators\csrf.py", line 54, in wrapped_view
    return view_func(*args, **kwargs)
  File "D:\Projects\Collegiate_Explorer_APP\collegiate-explorer-admin\cc_admin\apps\search\views.py", line 82, in index
    selected_tags = json.load(filter_content)
  File "C:\Users\AARON-PREDATOR\AppData\Local\Programs\Python\Python36\lib\json\__init__.py", line 296, in load
    return loads(fp.read(),
AttributeError: 'str' object has no attribute 'read'
[2020-10-28 16:57:38,550][Thread-1:10500][task_id:django.server][basehttp.py:157][ERROR]["POST /search/query HTTP/1.1" 500 84993]
[2020-11-02 04:25:35,703][Thread-2:139975495976704][task_id:django.request][log.py:224][ERROR][Internal Server Error: /recommendation/]
Traceback (most recent call last):
  File "/home/kptran/.local/lib/python3.8/site-packages/django/core/handlers/exception.py", line 47, in inner
    response = get_response(request)
  File "/home/kptran/.local/lib/python3.8/site-packages/django/core/handlers/base.py", line 179, in _get_response
    response = wrapped_callback(request, *callback_args, **callback_kwargs)
  File "/home/kptran/Project/backend2/cc_admin/apps/recommendation/views.py", line 82, in index
    connection = ConnectionPool()
NameError: name 'ConnectionPool' is not defined
[2020-11-02 04:25:35,721][Thread-2:139975495976704][task_id:django.server][basehttp.py:157][ERROR]["GET /recommendation/ HTTP/1.1" 500 62676]
[2020-11-02 04:26:11,944][Thread-2:140173549242112][task_id:django.request][log.py:224][ERROR][Internal Server Error: /recommendation/]
Traceback (most recent call last):
  File "/home/kptran/.local/lib/python3.8/site-packages/neo4j/io/__init__.py", line 929, in _connect
    s.connect(resolved_address)
ConnectionRefusedError: [Errno 111] Connection refused

During handling of the above exception, another exception occurred:

Traceback (most recent call last):
  File "/home/kptran/.local/lib/python3.8/site-packages/django/core/handlers/exception.py", line 47, in inner
    response = get_response(request)
  File "/home/kptran/.local/lib/python3.8/site-packages/django/core/handlers/base.py", line 179, in _get_response
    response = wrapped_callback(request, *callback_args, **callback_kwargs)
  File "/home/kptran/Project/backend2/cc_admin/apps/recommendation/views.py", line 83, in index
    connection = ConnectionPool()
  File "/home/kptran/Project/backend2/cc_admin/common/Neo4jConnectionPool.py", line 17, in __init__
    self.driver = GraphDatabase.driver(uri, auth=(user, pwd))
  File "/home/kptran/.local/lib/python3.8/site-packages/neo4j/__init__.py", line 183, in driver
    return cls.bolt_driver(parsed.netloc, auth=auth, **config)
  File "/home/kptran/.local/lib/python3.8/site-packages/neo4j/__init__.py", line 196, in bolt_driver
    return BoltDriver.open(target, auth=auth, **config)
  File "/home/kptran/.local/lib/python3.8/site-packages/neo4j/__init__.py", line 359, in open
    pool = BoltPool.open(address, auth=auth, pool_config=pool_config, workspace_config=default_workspace_config)
  File "/home/kptran/.local/lib/python3.8/site-packages/neo4j/io/__init__.py", line 531, in open
    seeds = [pool.acquire() for _ in range(pool_config.init_size)]
  File "/home/kptran/.local/lib/python3.8/site-packages/neo4j/io/__init__.py", line 531, in <listcomp>
    seeds = [pool.acquire() for _ in range(pool_config.init_size)]
  File "/home/kptran/.local/lib/python3.8/site-packages/neo4j/io/__init__.py", line 545, in acquire
    return self._acquire(self.address, timeout)
  File "/home/kptran/.local/lib/python3.8/site-packages/neo4j/io/__init__.py", line 409, in _acquire
    connection = self.opener(address, timeout)
  File "/home/kptran/.local/lib/python3.8/site-packages/neo4j/io/__init__.py", line 528, in opener
    return Bolt.open(addr, auth=auth, timeout=timeout, routing_context=routing_context, **pool_config)
  File "/home/kptran/.local/lib/python3.8/site-packages/neo4j/io/__init__.py", line 193, in open
    s, pool_config.protocol_version, handshake, data = connect(
  File "/home/kptran/.local/lib/python3.8/site-packages/neo4j/io/__init__.py", line 1049, in connect
    raise last_error
  File "/home/kptran/.local/lib/python3.8/site-packages/neo4j/io/__init__.py", line 1039, in connect
    s = _connect(resolved_address, timeout, keep_alive)
  File "/home/kptran/.local/lib/python3.8/site-packages/neo4j/io/__init__.py", line 943, in _connect
    raise ServiceUnavailable("Failed to establish connection to {!r} (reason {})".format(resolved_address, error))
neo4j.exceptions.ServiceUnavailable: Failed to establish connection to IPv4Address(('127.0.0.1', 7687)) (reason [Errno 111] Connection refused)
[2020-11-02 04:26:12,015][Thread-2:140173549242112][task_id:django.server][basehttp.py:157][ERROR]["GET /recommendation/ HTTP/1.1" 500 134557]
[2020-11-02 04:31:01,363][Thread-1:140173557696256][task_id:django.request][log.py:224][ERROR][Internal Server Error: /recommendation/]
Traceback (most recent call last):
  File "/home/kptran/.local/lib/python3.8/site-packages/neo4j/io/__init__.py", line 929, in _connect
    s.connect(resolved_address)
ConnectionRefusedError: [Errno 111] Connection refused

During handling of the above exception, another exception occurred:

Traceback (most recent call last):
  File "/home/kptran/.local/lib/python3.8/site-packages/django/core/handlers/exception.py", line 47, in inner
    response = get_response(request)
  File "/home/kptran/.local/lib/python3.8/site-packages/django/core/handlers/base.py", line 179, in _get_response
    response = wrapped_callback(request, *callback_args, **callback_kwargs)
  File "/home/kptran/Project/backend2/cc_admin/apps/recommendation/views.py", line 83, in index
    connection = ConnectionPool()
  File "/home/kptran/Project/backend2/cc_admin/common/Neo4jConnectionPool.py", line 17, in __init__
    self.driver = GraphDatabase.driver(uri, auth=(user, pwd))
  File "/home/kptran/.local/lib/python3.8/site-packages/neo4j/__init__.py", line 183, in driver
    return cls.bolt_driver(parsed.netloc, auth=auth, **config)
  File "/home/kptran/.local/lib/python3.8/site-packages/neo4j/__init__.py", line 196, in bolt_driver
    return BoltDriver.open(target, auth=auth, **config)
  File "/home/kptran/.local/lib/python3.8/site-packages/neo4j/__init__.py", line 359, in open
    pool = BoltPool.open(address, auth=auth, pool_config=pool_config, workspace_config=default_workspace_config)
  File "/home/kptran/.local/lib/python3.8/site-packages/neo4j/io/__init__.py", line 531, in open
    seeds = [pool.acquire() for _ in range(pool_config.init_size)]
  File "/home/kptran/.local/lib/python3.8/site-packages/neo4j/io/__init__.py", line 531, in <listcomp>
    seeds = [pool.acquire() for _ in range(pool_config.init_size)]
  File "/home/kptran/.local/lib/python3.8/site-packages/neo4j/io/__init__.py", line 545, in acquire
    return self._acquire(self.address, timeout)
  File "/home/kptran/.local/lib/python3.8/site-packages/neo4j/io/__init__.py", line 409, in _acquire
    connection = self.opener(address, timeout)
  File "/home/kptran/.local/lib/python3.8/site-packages/neo4j/io/__init__.py", line 528, in opener
    return Bolt.open(addr, auth=auth, timeout=timeout, routing_context=routing_context, **pool_config)
  File "/home/kptran/.local/lib/python3.8/site-packages/neo4j/io/__init__.py", line 193, in open
    s, pool_config.protocol_version, handshake, data = connect(
  File "/home/kptran/.local/lib/python3.8/site-packages/neo4j/io/__init__.py", line 1049, in connect
    raise last_error
  File "/home/kptran/.local/lib/python3.8/site-packages/neo4j/io/__init__.py", line 1039, in connect
    s = _connect(resolved_address, timeout, keep_alive)
  File "/home/kptran/.local/lib/python3.8/site-packages/neo4j/io/__init__.py", line 943, in _connect
    raise ServiceUnavailable("Failed to establish connection to {!r} (reason {})".format(resolved_address, error))
neo4j.exceptions.ServiceUnavailable: Failed to establish connection to IPv4Address(('127.0.0.1', 7687)) (reason [Errno 111] Connection refused)
[2020-11-02 04:31:01,416][Thread-1:140173557696256][task_id:django.server][basehttp.py:157][ERROR]["GET /recommendation/ HTTP/1.1" 500 134557]
[2020-11-02 04:32:35,121][Thread-2:140268013291264][task_id:django.request][log.py:224][ERROR][Internal Server Error: /recommendation/]
Traceback (most recent call last):
  File "/home/kptran/.local/lib/python3.8/site-packages/django/core/handlers/exception.py", line 47, in inner
    response = get_response(request)
  File "/home/kptran/.local/lib/python3.8/site-packages/django/core/handlers/base.py", line 179, in _get_response
    response = wrapped_callback(request, *callback_args, **callback_kwargs)
  File "/home/kptran/Project/backend2/cc_admin/apps/recommendation/views.py", line 115, in index
    cc_score = float(school['node_cc_score'])
UnboundLocalError: local variable 'school' referenced before assignment
[2020-11-02 04:32:35,373][Thread-3:140268004837120][task_id:django.request][log.py:224][ERROR][Internal Server Error: /recommendation/]
Traceback (most recent call last):
  File "/home/kptran/.local/lib/python3.8/site-packages/django/core/handlers/exception.py", line 47, in inner
    response = get_response(request)
  File "/home/kptran/.local/lib/python3.8/site-packages/django/core/handlers/base.py", line 179, in _get_response
    response = wrapped_callback(request, *callback_args, **callback_kwargs)
  File "/home/kptran/Project/backend2/cc_admin/apps/recommendation/views.py", line 115, in index
    cc_score = float(school['node_cc_score'])
UnboundLocalError: local variable 'school' referenced before assignment
[2020-11-02 04:32:35,390][Thread-3:140268004837120][task_id:django.server][basehttp.py:157][ERROR]["GET /recommendation/ HTTP/1.1" 500 69190]
[2020-11-02 04:34:12,747][Thread-2:140545447167744][task_id:django.request][log.py:224][ERROR][Internal Server Error: /recommendation/]
Traceback (most recent call last):
  File "/home/kptran/.local/lib/python3.8/site-packages/django/core/handlers/exception.py", line 47, in inner
    response = get_response(request)
  File "/home/kptran/.local/lib/python3.8/site-packages/django/core/handlers/base.py", line 179, in _get_response
    response = wrapped_callback(request, *callback_args, **callback_kwargs)
  File "/home/kptran/Project/backend2/cc_admin/apps/recommendation/views.py", line 118, in index
    cc_score = float(school['node_cc_score'])
KeyError: 'node_cc_score'
[2020-11-02 04:34:12,753][Thread-2:140545447167744][task_id:django.server][basehttp.py:157][ERROR]["GET /recommendation/ HTTP/1.1" 500 70149]
[2020-11-02 04:43:39,910][Thread-2:139753403909888][task_id:django.request][log.py:224][ERROR][Internal Server Error: /detail/e19cb127-23b1-4100-bfdc-59c0789c58db]
Traceback (most recent call last):
  File "/home/kptran/.local/lib/python3.8/site-packages/django/core/handlers/exception.py", line 47, in inner
    response = get_response(request)
  File "/home/kptran/.local/lib/python3.8/site-packages/django/core/handlers/base.py", line 179, in _get_response
    response = wrapped_callback(request, *callback_args, **callback_kwargs)
  File "/home/kptran/Project/backend2/cc_admin/apps/detail/views.py", line 101, in get_basic_info
    connection = ConnectionPool()
NameError: name 'ConnectionPool' is not defined
[2020-11-02 04:43:39,922][Thread-2:139753403909888][task_id:django.server][basehttp.py:157][ERROR]["GET /detail/e19cb127-23b1-4100-bfdc-59c0789c58db HTTP/1.1" 500 63091]
[2020-11-02 05:12:59,256][Thread-8:139766435088128][task_id:django.request][log.py:224][ERROR][Internal Server Error: /detail/e19cb127-23b1-4100-bfdc-59c0789c58db]
Traceback (most recent call last):
  File "/home/kptran/.local/lib/python3.8/site-packages/neo4j/io/__init__.py", line 929, in _connect
    s.connect(resolved_address)
ConnectionRefusedError: [Errno 111] Connection refused

During handling of the above exception, another exception occurred:

Traceback (most recent call last):
  File "/home/kptran/.local/lib/python3.8/site-packages/django/core/handlers/exception.py", line 47, in inner
    response = get_response(request)
  File "/home/kptran/.local/lib/python3.8/site-packages/django/core/handlers/base.py", line 179, in _get_response
    response = wrapped_callback(request, *callback_args, **callback_kwargs)
  File "/home/kptran/Project/backend2/cc_admin/apps/detail/views.py", line 101, in get_basic_info
    connection = ConnectionPool()
  File "/home/kptran/Project/backend2/cc_admin/common/Neo4jConnectionPool.py", line 17, in __init__
    self.driver = GraphDatabase.driver(uri, auth=(user, pwd))
  File "/home/kptran/.local/lib/python3.8/site-packages/neo4j/__init__.py", line 183, in driver
    return cls.bolt_driver(parsed.netloc, auth=auth, **config)
  File "/home/kptran/.local/lib/python3.8/site-packages/neo4j/__init__.py", line 196, in bolt_driver
    return BoltDriver.open(target, auth=auth, **config)
  File "/home/kptran/.local/lib/python3.8/site-packages/neo4j/__init__.py", line 359, in open
    pool = BoltPool.open(address, auth=auth, pool_config=pool_config, workspace_config=default_workspace_config)
  File "/home/kptran/.local/lib/python3.8/site-packages/neo4j/io/__init__.py", line 531, in open
    seeds = [pool.acquire() for _ in range(pool_config.init_size)]
  File "/home/kptran/.local/lib/python3.8/site-packages/neo4j/io/__init__.py", line 531, in <listcomp>
    seeds = [pool.acquire() for _ in range(pool_config.init_size)]
  File "/home/kptran/.local/lib/python3.8/site-packages/neo4j/io/__init__.py", line 545, in acquire
    return self._acquire(self.address, timeout)
  File "/home/kptran/.local/lib/python3.8/site-packages/neo4j/io/__init__.py", line 409, in _acquire
    connection = self.opener(address, timeout)
  File "/home/kptran/.local/lib/python3.8/site-packages/neo4j/io/__init__.py", line 528, in opener
    return Bolt.open(addr, auth=auth, timeout=timeout, routing_context=routing_context, **pool_config)
  File "/home/kptran/.local/lib/python3.8/site-packages/neo4j/io/__init__.py", line 193, in open
    s, pool_config.protocol_version, handshake, data = connect(
  File "/home/kptran/.local/lib/python3.8/site-packages/neo4j/io/__init__.py", line 1049, in connect
    raise last_error
  File "/home/kptran/.local/lib/python3.8/site-packages/neo4j/io/__init__.py", line 1039, in connect
    s = _connect(resolved_address, timeout, keep_alive)
  File "/home/kptran/.local/lib/python3.8/site-packages/neo4j/io/__init__.py", line 943, in _connect
    raise ServiceUnavailable("Failed to establish connection to {!r} (reason {})".format(resolved_address, error))
neo4j.exceptions.ServiceUnavailable: Failed to establish connection to IPv4Address(('127.0.0.1', 11003)) (reason [Errno 111] Connection refused)
[2020-11-02 05:12:59,315][Thread-8:139766435088128][task_id:django.server][basehttp.py:157][ERROR]["GET /detail/e19cb127-23b1-4100-bfdc-59c0789c58db HTTP/1.1" 500 135000]
[2020-11-02 05:13:53,589][Thread-2:139838240720640][task_id:django.request][log.py:224][ERROR][Internal Server Error: /detail/e19cb127-23b1-4100-bfdc-59c0789c58db]
Traceback (most recent call last):
  File "/home/kptran/.local/lib/python3.8/site-packages/django/core/handlers/exception.py", line 47, in inner
    response = get_response(request)
  File "/home/kptran/.local/lib/python3.8/site-packages/django/core/handlers/base.py", line 179, in _get_response
    response = wrapped_callback(request, *callback_args, **callback_kwargs)
  File "/home/kptran/Project/backend2/cc_admin/apps/detail/views.py", line 167, in get_basic_info
    'location': detail['address'] + ' ' + detail['city'] + ', ' + detail['state'] + ' ' + detail['zip'],
KeyError: 'zip'
[2020-11-02 05:13:53,602][Thread-2:139838240720640][task_id:django.server][basehttp.py:157][ERROR]["GET /detail/e19cb127-23b1-4100-bfdc-59c0789c58db HTTP/1.1" 500 71200]
[2020-11-02 06:19:14,648][Thread-5:139906909341440][task_id:django.request][log.py:224][ERROR][Internal Server Error: /detail/fame/e19cb127-23b1-4100-bfdc-59c0789c58db]
Traceback (most recent call last):
  File "/home/kptran/.local/lib/python3.8/site-packages/django/core/handlers/exception.py", line 47, in inner
    response = get_response(request)
  File "/home/kptran/.local/lib/python3.8/site-packages/django/core/handlers/base.py", line 179, in _get_response
    response = wrapped_callback(request, *callback_args, **callback_kwargs)
  File "/home/kptran/Project/backend2/cc_admin/apps/detail/views.py", line 208, in get_fame_property
    result = connection.executeQuery(
NameError: name 'connection' is not defined
[2020-11-02 06:19:14,672][Thread-5:139906909341440][task_id:django.server][basehttp.py:157][ERROR]["GET /detail/fame/e19cb127-23b1-4100-bfdc-59c0789c58db HTTP/1.1" 500 63053]
[2020-11-02 06:57:16,227][Thread-7:140069620877056][task_id:django.request][log.py:224][ERROR][Internal Server Error: /detail/score/92d5a875-8431-4bfd-8baf-bfb061e6181b]
Traceback (most recent call last):
  File "/home/kptran/.local/lib/python3.8/site-packages/django/core/handlers/exception.py", line 47, in inner
    response = get_response(request)
  File "/home/kptran/.local/lib/python3.8/site-packages/django/core/handlers/base.py", line 179, in _get_response
    response = wrapped_callback(request, *callback_args, **callback_kwargs)
  File "/home/kptran/Project/backend2/cc_admin/apps/detail/views.py", line 383, in get_score_data
    {'item': 'SAT_reading', 'score': int(detail['read_sat'])/10},  # div 10
ValueError: invalid literal for int() with base 10: 'N/A'
[2020-11-02 06:57:16,248][Thread-7:140069620877056][task_id:django.server][basehttp.py:157][ERROR]["GET /detail/score/92d5a875-8431-4bfd-8baf-bfb061e6181b HTTP/1.1" 500 70915]
[2020-11-02 06:57:21,244][Thread-8:140069995480832][task_id:django.request][log.py:224][ERROR][Internal Server Error: /detail/score/47ceca34-5c35-4a70-9dd3-a7f3d14c13ef]
Traceback (most recent call last):
  File "/home/kptran/.local/lib/python3.8/site-packages/django/core/handlers/exception.py", line 47, in inner
    response = get_response(request)
  File "/home/kptran/.local/lib/python3.8/site-packages/django/core/handlers/base.py", line 179, in _get_response
    response = wrapped_callback(request, *callback_args, **callback_kwargs)
  File "/home/kptran/Project/backend2/cc_admin/apps/detail/views.py", line 387, in get_score_data
    {'item': 'GPA', 'score': int(float(detail['gpa'])*20)}  # * 20
ValueError: could not convert string to float: 'N/A'
[2020-11-02 06:57:21,289][Thread-8:140069995480832][task_id:django.server][basehttp.py:157][ERROR]["GET /detail/score/47ceca34-5c35-4a70-9dd3-a7f3d14c13ef HTTP/1.1" 500 70216]
[2020-11-02 07:00:31,460][Thread-2:140485777032960][task_id:django.request][log.py:224][ERROR][Internal Server Error: /recommendation/]
Traceback (most recent call last):
  File "/home/kptran/.local/lib/python3.8/site-packages/django/core/handlers/exception.py", line 47, in inner
    response = get_response(request)
  File "/home/kptran/.local/lib/python3.8/site-packages/django/core/handlers/base.py", line 179, in _get_response
    response = wrapped_callback(request, *callback_args, **callback_kwargs)
  File "/home/kptran/Project/backend2/cc_admin/apps/recommendation/views.py", line 129, in index
    print(cc_ratomg)
NameError: name 'cc_ratomg' is not defined
[2020-11-02 07:00:31,466][Thread-2:140485777032960][task_id:django.server][basehttp.py:157][ERROR]["GET /recommendation/ HTTP/1.1" 500 71144]
[2020-11-02 07:01:35,745][Thread-2:139869554542336][task_id:django.request][log.py:224][ERROR][Internal Server Error: /recommendation/]
Traceback (most recent call last):
  File "/home/kptran/.local/lib/python3.8/site-packages/django/core/handlers/exception.py", line 47, in inner
    response = get_response(request)
  File "/home/kptran/.local/lib/python3.8/site-packages/django/core/handlers/base.py", line 179, in _get_response
    response = wrapped_callback(request, *callback_args, **callback_kwargs)
  File "/home/kptran/Project/backend2/cc_admin/apps/recommendation/views.py", line 125, in index
    if cc_score in range(cc_min,cc_max):
TypeError: 'float' object cannot be interpreted as an integer
[2020-11-02 07:01:35,752][Thread-2:139869554542336][task_id:django.server][basehttp.py:157][ERROR]["GET /recommendation/ HTTP/1.1" 500 71126]
[2020-11-02 07:29:42,460][Thread-6:140308273694464][task_id:django.request][log.py:224][ERROR][Internal Server Error: /detail/score/d9b90eb1-d6dd-4115-87fc-95a5a6b5340a]
Traceback (most recent call last):
  File "/home/kptran/.local/lib/python3.8/site-packages/django/core/handlers/exception.py", line 47, in inner
    response = get_response(request)
  File "/home/kptran/.local/lib/python3.8/site-packages/django/core/handlers/base.py", line 179, in _get_response
    response = wrapped_callback(request, *callback_args, **callback_kwargs)
  File "/home/kptran/Project/backend2/cc_admin/apps/detail/views.py", line 358, in get_score_data
    {'item': 'SAT_reading', 'score': int(detail['read_sat'])/10},  # div 10
ValueError: invalid literal for int() with base 10: 'N/A'
[2020-11-02 07:29:42,465][Thread-6:140308273694464][task_id:django.server][basehttp.py:157][ERROR]["GET /detail/score/d9b90eb1-d6dd-4115-87fc-95a5a6b5340a HTTP/1.1" 500 70395]
